Workbook

Sheet Matriz comparativa
A1: # | B1: Sección | C1: Original | D1: FACILE | E1: Placea | F1: Asistente de lectura fácil “ANTONIO GONZALES CRESPO” | G1: Asistente de lectura fácil “Mark Jonathan Camacho Escatel”: | H1: Gemini 3.1 Pro | I1: GPT 5.4 Think | J1: Claude Sonnet 4.6 | K1: deepseek-v3.2 | L1: SimpleText (ClearText) | M1: Modelo_Qwen3.5_9B | N1: Asistente Lectura Facilitada "Francisco Javier Alvarez Jimenez"
B2: Check-list | C2: ='1'!D9 -> 4.5 | D2: ='2'!D9 -> 4.5 | E2: ='3'!D9 -> 4.5 | F2: ='4'!D9 -> 4.5 | G2: ='5'!D9 -> 3.5 | H2: ='6'!D9 -> 4.5 | I2: ='7'!D9 -> 4.5 | J2: ='8'!D9 -> 4.5 | K2: ='9'!D9 -> 4.5 | L2: ='10'!D9 -> 4 | M2: ='11'!D9 -> 2.5 | N2: ='12'!D9 -> 4
A4: 1 | B4: Título | C4: Información sobre protección de datos | D4: Información sobre protección de datos. | E4: INFORMACIÓN SOBRE PROTECCIÓN DE DATOS | F4: Información sobre protección de datos | G4: Información sobre protección de datos | H4: Información sobre la protección de tus datos | I4: Información sobre tus datos | J4: Protección de tus datos personales | K4: Información sobre protección de datos | L4: Información sobre protección de datos | N4: Información sobre tus datos
A5: 2 | B5: Responsable | C5: por la Universidad Politécnica de Madrid (Grupo de Ingeniería Ontológica), responsable de este tratamiento, | D5: sean tratados por la Universidad Politécnica de Madrid (Grupo de Ingeniería Ontológica), responsable de este tratamiento, | E5: aceptas que la Universidad Politécnica de Madrid (Grupo de Ingeniería Ontológica) use tus datos. | F5: El grupo responsable es el Grupo de Ingeniería Ontológica. | G5: La responsable del tratamiento de los datos es la Universidad Politécnica de Madrid. | H5: El Grupo de Ingeniería Ontológica es el responsable de tus datos. | I5: La Universidad Politécnica de Madrid. Grupo de Ingeniería Ontológica. Es la responsable del uso de tus datos. | J5: El grupo responsable es el Grupo de Ingeniería Ontológica. | K5: La responsable del tratamiento de tus datos es la Universidad Politécnica de Madrid (Grupo de Ingeniería Ontológica). | L5: que tus datos sean tratados por la Universidad Politécnica de Madrid( Grupo de Ingeniería Ontológica), responsable de este tratamiento, | M5: La Universidad Politécnica Madrid (Grupo de Investigación Ontológica) | N5: La Universidad Politécnica de Madrid es la responsable del tratamiento de los datos.
A6: 3 | B6: Finalidad | C6: finalidad relacionada con la investigación ya señalada. | D6: finalidad relacionada con la investigación ya señalada. | E6: Esto es para la investigación que hemos mencionado. | F6: La Universidad Politécnica de Madrid usa tus datos para una investigación. | G6: Si completas el cuestionario, aceptas que tus datos se usen para esta investigación. | H6: Esta universidad usa tus datos para investigar | I6: La finalidad es la investigación indicada antes en este cuestionario. | J6: Tus datos sirven para hacer la investigación explicada en este cuestionario. | K6: Usamos tus datos para la investigación que te explicamos. | L6: con la finalidad relacionada con la investigación ya señalada. | M6: quiere investigar sobre la lectura fácil. | N6: Tus datos se usarán para la investigación relacionada con este cuestionario.
A7: 4 | B7: Legitimación | C7: que tus datos sean tratados | D7: que tus datos sean tratados | E7: use tus datos. | F7: usa tus datos para una investigación. | G7: que tus datos se usen para esta investigación. | H7: usa tus datos | I7: use tus datos. | J7: use tus datos | K7: nos das permiso para usar tus datos | L7: de que consientes que tus datos sean tratados | N7: El tratamiento de datos significa recoger y usar información.
A8: 5 | B8: Destinatarios
A9: 6 | B9: Derechos | C9: También te informamos de que puedes acceder, rectificar y suprimir los datos, así como ejercer otros derechos, en los términos que se indican en la información adicional, disponible en el siguiente enlace: "https://oeg.fi.upm.es/protecciondatos.html". | D9: También te informamos de que puedes acceder, rectificar y suprimir los datos, así como ejercer otros derechos, en los términos que se indican en la información adicional, disponible en el siguiente enlace: "https://oeg.fi.upm.es/protecciondatos.html". | E9: También puedes acceder, cambiar y borrar tus datos. Tienes otros derechos que puedes ejercer. Para más información, puedes visitar este enlace: "https://oeg.fi.upm.es/protecciondatos.html". | F9: Ver tus datos. Cambiar tus datos. Pedir que eliminen tus datos. Usar otros derechos relacionados con la protección de datos. Puedes leer más información en este enlace: https://oeg.fi.upm.es/protecciondatos.html | G9: Puedes: Consultar tus datos. Cambiar tus datos. Pedir que se eliminen tus datos. Ejercer otros derechos relacionados con la protección de datos. Puedes leer más información aquí: Protección de datos UPM | H9: Tú tienes derechos sobre tu información personal. Tú puedes pedir estas cuatro acciones: Ver tus datos. Cambiar tus datos. Borrar tus datos. Pedir otros derechos. Tú puedes leer más información sobre tus derechos. Tú puedes encontrar la información en esta página web: https://oeg.fi.upm.es/protecciondatos.html | I9: us derechos Tú puedes hacer lo siguiente con tus datos: Acceder a tus datos. Rectificar tus datos. Suprimir tus datos. Ejercer otros derechos sobre tus datos. Rectificar Quiere decir corregir tus datos si hay un error o si han cambiado. Suprimir Quiere decir pedir que borren tus datos. Dónde puedes leer más información Puedes leer la información adicional en este enlace: https://oeg.fi.upm.es/protecciondatos.html | J9: Tienes derecho a: → Ver qué datos tenemos sobre ti → Corregir tus datos si son incorrectos → Pedir que borremos tus datos → Ejercer otros derechos que te explicamos en el enlace de abajo Más información sobre tus derechos: oeg.fi.upm.es/protecciondatos.html | K9: Tienes derecho a: - acceder a tus datos Puedes ver tus datos cuando quieras. - rectificar tus datos Puedes corregir tus datos si son incorrectos. - suprimir tus datos Puedes borrar tus datos cuando quieras. - ejercer otros derechos Puedes obtener más información sobre tus derechos en este enlace: https://oeg.fi.upm.es/protecciondatos.html | L9: También te informamos de que puedes acceder, rectificar y suprimir los datos, y ejercer otros derechos, en los términos que se indican en la información adicional, disponible en el siguiente enlace que https: //oeg.fi.upm.es/ protecciondatos.html. | M9: Si quieres saber cómo se usan los datos, puedes ver la política de privacidad en este enlace: https://oeg.fi. upm.es/proteccióndatos.html | N9: Tus datos se usarán para la investigación relacionada con este cuestionario. Tú tienes varios derechos sobre tus datos: Tú puedes ver tus datos. Tú puedes corregir tus datos. Tú puedes pedir que tus datos se eliminen. Tú puedes ejercer otros derechos relacionados con la protección de datos. Puedes leer más información en este enlace: https://oeg.fi.upm.es/protecciondatos.html
A10: 7 | B10: Procedencia
B11: MODELO | E11: GPT-3.5 | F11: GPT-5.3 | G11: GPT-5.3 | H11: Gemini 3.1 Pro | I11: GPT 5.4 Think | J11: Sonnet 4.6 Thinking | K11: deepseek-v3.2 | N11: GPT-5.3
B12: TIEMPO DE ADAPTACIÓN [segundos] | E12: 52 | F12: 31 | G12: 22 | H12: 22 | I12: 33 | J12: 31 | K12: 45 | L12: 6
B13: ITERACIONES | E13: 1 | F13: 1 | G13: 1 | H13: 1 | I13: 1 | J13: 1 | K13: 1 | L13: 1 | N13: 1
B14: TEXTO ADAPTADO (SALIDA DE CADA HERRAMIENTA DE LF) | C14: Información sobre protección de datos Este cuestionario ha sido diseñado de forma que se preserve totalmente su carácter anónimo. No obstante, consideramos oportuno informarte en relación con nuestra política de privacidad, conforme a lo establecido en la normativa de protección de datos de carácter personal. Si accedes a cumplimentar el cuestionario te informamos de que consientes que tus datos sean tratados por la Universidad Politécnica de Madrid (Grupo de Ingeniería Ontológica), responsable de este tratamiento, con la finalidad relacionada con la investigación ya señalada. También te informamos de que puedes acceder, rectificar y suprimir los datos, así como ejercer otros derechos, en los términos que se indican en la información adicional, disponible en el siguiente enlace: "https://oeg.fi.upm.es/protecciondatos.html". | D14: Información sobre protección de datos. Se ha diseñado este cuestionario de forma que se preserve del todo su carácter anónimo. Consideramos oportuno informarte en relación con nuestra política de privacidad, conforme a lo establecido en la normativa de protección de datos de carácter personal. Si accedes a cumplimentar el cuestionario te informamos de que consientes que tus datos sean tratados por la Universidad Politécnica de Madrid (Grupo de Ingeniería Ontológica), responsable de este tratamiento, con la finalidad relacionada con la investigación ya señalada. También te informamos de que puedes acceder, rectificar y suprimir los datos, así como ejercer otros derechos, en los términos que se indican en la información adicional, disponible en el siguiente enlace: "https://oeg.fi.upm.es/protecciondatos.html". | E14: INFORMACIÓN SOBRE PROTECCIÓN DE DATOS Este cuestionario es anónimo. Esto significa que no se sabe quién lo responde. Pero queremos informarte sobre nuestra política de privacidad. Esto es importante según las leyes de protección de datos. Si decides responder el cuestionario, aceptas que la Universidad Politécnica de Madrid (Grupo de Ingeniería Ontológica) use tus datos. Esto es para la investigación que hemos mencionado. También puedes acceder, cambiar y borrar tus datos. Tienes otros derechos que puedes ejercer. Para más información, puedes visitar este enlace: "https://oeg.fi.upm.es/protecciondatos.html". | F14: Información sobre protección de datos Este cuestionario es anónimo. Nadie puede saber quién responde. La Universidad Politécnica de Madrid usa tus datos para una investigación. El grupo responsable es el Grupo de Ingeniería Ontológica. Si completas el cuestionario, aceptas el uso de tus datos para esta investigación. Tú puedes: Ver tus datos. Cambiar tus datos. Pedir que eliminen tus datos. Usar otros derechos relacionados con la protección de datos. Puedes leer más información en este enlace: https://oeg.fi.upm.es/protecciondatos.html | G14: Información sobre protección de datos Este cuestionario es anónimo. Esto significa que no recogerá información para identificarte. La información que escribas se usará para una investigación. La responsable del tratamiento de los datos es la Universidad Politécnica de Madrid. Si completas el cuestionario, aceptas que tus datos se usen para esta investigación. Puedes: Consultar tus datos. Cambiar tus datos. Pedir que se eliminen tus datos. Ejercer otros derechos relacionados con la protección de datos. Puedes leer más información aquí: Protección de datos UPM | H14: Información sobre la protección de tus datos Este cuestionario es anónimo. Anónimo Significa que nadie sabe tu nombre ni quién eres. Ejemplo: Un examen sin nombre es anónimo. Nosotros queremos informar sobre nuestra política de privacidad. Política de privacidad Son las normas para proteger la información de las personas. Ejemplo: La universidad usa la política de privacidad para cuidar tu información. La ley obliga a proteger los datos personales. Tú decides responder las preguntas. Con esta acción tú das permiso para usar tus datos. La Universidad Politécnica de Madrid usa tus datos. Esta universidad usa tus datos para investigar. El Grupo de Ingeniería Ontológica es el responsable de tus datos. Tú tienes derechos sobre tu información personal. Tú puedes pedir estas cuatro acciones: Ver tus datos. Cambiar tus datos. Borrar tus datos. Pedir otros derechos. Tú puedes leer más información sobre tus derechos. Tú puedes encontrar la información en esta página web: https://oeg.fi.upm.es/protecciondatos.html | I14: Información sobre tus datos Este cuestionario es anónimo. Anónimo Esto quiere decir que nadie puede saber que las respuestas son tuyas. Queremos informarte sobre cómo protegemos tus datos personales. Esta información sigue la norma sobre protección de datos personales. Quién usa tus datos y para qué Si decides rellenar el cuestionario, aceptas que la Universidad Politécnica de Madrid use tus datos. Usar tus datos Quiere decir recoger, guardar o consultar tus datos para una finalidad concreta. La Universidad Politécnica de Madrid. Grupo de Ingeniería Ontológica. Es la responsable del uso de tus datos. La finalidad es la investigación indicada antes en este cuestionario. Tus derechos Tú puedes hacer lo siguiente con tus datos: Acceder a tus datos. Rectificar tus datos. Suprimir tus datos. Ejercer otros derechos sobre tus datos. Rectificar Quiere decir corregir tus datos si hay un error o si han cambiado. Suprimir Quiere decir pedir que borren tus datos. Dónde puedes leer más información Puedes leer la información adicional en este enlace: https://oeg.fi.upm.es/protecciondatos.html | J14: Protección de tus datos personales Este cuestionario es anónimo. Esto quiere decir que no guardamos tu nombre ni tus datos personales. ¿Quién usa tus datos? Si completas el cuestionario, aceptas que la Universidad Politécnica de Madrid use tus datos. El grupo responsable es el Grupo de Ingeniería Ontológica. ¿Para qué usan tus datos? Tus datos sirven para hacer la investigación explicada en este cuestionario. Tus derechos sobre tus datos Tienes derecho a: → Ver qué datos tenemos sobre ti → Corregir tus datos si son incorrectos → Pedir que borremos tus datos → Ejercer otros derechos que te explicamos en el enlace de abajo Más información sobre tus derechos: oeg.fi.upm.es/protecciondatos.html | K14: Información sobre protección de datos Diseñamos este cuestionario para que sea anónimo. Esto significa que no podemos saber quién responde. Queremos informarte sobre nuestra política de privacidad. La política de privacidad son las normas que seguimos para proteger tus datos personales. Si decides responder el cuestionario, nos das permiso para usar tus datos. La responsable del tratamiento de tus datos es la Universidad Politécnica de Madrid (Grupo de Ingeniería Ontológica). Ser responsable del tratamiento significa que esta universidad decide cómo y por qué se usan tus datos. Usamos tus datos para la investigación que te explicamos. Tienes derecho a: - acceder a tus datos Puedes ver tus datos cuando quieras. - rectificar tus datos Puedes corregir tus datos si son incorrectos. - suprimir tus datos Puedes borrar tus datos cuando quieras. - ejercer otros derechos Puedes obtener más información sobre tus derechos en este enlace: https://oeg.fi.upm.es/protecciondatos.html | L14: Información sobre protección de datos Este cuestionario ha sido diseñado de forma que se preserve de manera total su carácter anónimo. Pero, consideramos oportuno informarte en relación con nuestra política de privacidad, conforme a lo establecido en la normativa de protección de datos de carácter personal. Si accedes a cumplimentar el cuestionario te informamos de que consientes que tus datos sean tratados por la Universidad Politécnica de Madrid( Grupo de Ingeniería Ontológica), responsable de este tratamiento, con la finalidad relacionada con la investigación ya señalada. También te informamos de que puedes acceder, rectificar y suprimir los datos, y ejercer otros derechos, en los términos que se indican en la información adicional, disponible en el siguiente enlace que https: //oeg.fi.upm.es/ protecciondatos.html. | M14: La Universidad Politécnica Madrid (Grupo de Investigación Ontológica) quiere investigar sobre la lectura fácil. Para ello, han creado este cuestionario. Este cuestionario es anónimo. Esto significa que no podrás saber quién ha contestado. Si quieres saber cómo se usan los datos, puedes ver la política de privacidad en este enlace: https://oeg.fi. upm.es/proteccióndatos.html | N14: Información sobre tus datos Este cuestionario es anónimo. Anónimo significa que nadie puede saber quién eres por tus respuestas. Queremos explicarte cómo usamos la información. Si completas el cuestionario, aceptas que la Universidad Politécnica de Madrid use los datos que facilites. La Universidad Politécnica de Madrid es la responsable del tratamiento de los datos. El tratamiento de datos significa recoger y usar información. Tus datos se usarán para la investigación relacionada con este cuestionario. Tú tienes varios derechos sobre tus datos: Tú puedes ver tus datos. Tú puedes corregir tus datos. Tú puedes pedir que tus datos se eliminen. Tú puedes ejercer otros derechos relacionados con la protección de datos. Puedes leer más información en este enlace: https://oeg.fi.upm.es/protecciondatos.html
B15: PROMPT (SI EXISTIERA) | F15: Prompt: adapta el siguiente texto a lectura fácil: [TEXTO] | G15: Prompt: adapta el siguiente texto a lectura fácil: [TEXTO] | H15: 1. Instrucciones generales - Actúa como un experto adaptador de textos a Lectura Fácil. - Tu tarea es transformar el texto original proporcionado respetando estrictamente el sentido y el carácter del original. - Debes conservar la información relevante sin incluir opiniones personales o sesgos. - No incluyas explicaciones sobre los cambios aplicados en la simplificación; genera únicamente el texto adaptado y estructurado. 2. Objetivo general - El documento resultante debe estar destinado a personas con dificultades de comprensión lectora, como personas con discapacidad intelectual, personas mayores o personas que no dominan el idioma. - Si el texto aborda la protección de datos, el objetivo primordial es facilitar que el usuario comprenda sus derechos, sepa cómo decidir sobre el uso de sus datos y entienda cómo estos deben protegerse. 3. Signos de puntuación y símbolos - No debes escribir palabras ni frases con todas sus letras en mayúsculas, excepto cuando se trate de siglas. - Debes utilizar el punto y aparte para separar frases u oraciones que presenten ideas diferentes. - Las ideas enlazadas se deberían separar mediante un punto en lugar de una coma. EJEMPLO: Incorrecto: Como ayer estaba lloviendo, Juan cogió el paraguas. Correcto: Ayer estaba lloviendo. Por eso, Juan cogió el paraguas. - No se debe utilizar el punto y coma (;). - No se debe utilizar etcétera, ni los puntos suspensivos (...). Se puede sustituir por entre otros, y muchos más y otras frases similares. - Se deberían utilizar los dos puntos (:) cuando se introduce una lista que enumera más de tres elementos. 4. Formato de línea - Se debe presentar una sola idea principal por línea o bloque. - No deberían dividirse los sintagmas al cambiar de línea; las palabras accesorias (artículos, preposiciones) que queden al final de una línea deberían pasar al inicio de la siguiente. EJEMPLO: Incorrecto: Juan tiene un coche de color rojo. Correcto: Juan tiene un coche de color rojo. Correcto: Juan tiene un coche de color rojo. - Siempre que sea posible, si hay varios elementos (como una enumeración de derechos o tareas), se debe utilizar un listado hacia abajo. 5. Léxico - Se debe utilizar un lenguaje sencillo, claro y de uso frecuente. - Se deben evitar los adverbios terminados en "-mente". EJEMPLO: Incorrecto: Él habla claramente. Correcto: Él habla muy claro. - Se deben evitar los superlativos y sustituirlos añadiendo el adverbio "muy" al adjetivo. - Se debe utilizar a lo largo del texto la misma palabra para denominar el mismo objeto, derecho o referente. - Glosas: Debería usarse una glosa (explicación) cuando sea necesario incluir palabras técnicas o complejas. La palabra a definir debe ir en negrita, seguida de una explicación sencilla en la siguiente línea y, si es posible, un ejemplo de uso. La glosa debe usarse la primera vez que aparece la palabra o expresión que explica. 6. Números - Se deberían escribir los números en cifra. - Se debería evitar el uso de números ordinales y sustituirlos por números cardinales (ej. planta número 18 en vez de decimoctava). - Se debería evitar el uso de fracciones y porcentajes y sustituirlos por descripciones cualitativas. EJEMPLO: Incorrecto: El 25% de la población. Correcto: Una de cada cuatro personas. - Se debería escribir la fecha completa (ej. 12 de abril de 2020) y evitar guiones o barras. 7. Morfosintaxis - Se deberían utilizar frases sencillas y evitar oraciones complejas o subordinadas excesivas. - Se debería utilizar el presente de indicativo siempre que sea posible. - Se debe evitar el uso de la voz pasiva y la pasiva refleja. EJEMPLO VOZ PASIVA: Incorrecto: El martillo es usado por Juan en su trabajo. Correcto: Juan usa el martillo en su trabajo. EJEMPLO PASIVA REFLEJA: Incorrecto: Se venden casas. Correcto: Vendemos casas. - Se debería evitar en lo posible el uso de oraciones con gerundio. - Se deberían usar preferentemente oraciones afirmativas. En caso de necesitar una negación, la oración debe ser clara y evitar la doble negación. - El texto debería dirigirse directamente al lector siempre que sea posible y requiera o explicite una actuación del mismo. EJEMPLO: Incorrecto: Meter el pollo en el horno a 180°. Correcto: Mete el pollo en el horno a 180 grados. 8. Estructura de la información - Se debe mantener la cohesión y coherencia del texto a lo largo de todo el documento. - Se debería agrupar la información sobre un mismo tema en bloques de texto separados. - La redacción de los títulos debería hacer referencia o anticipar la información del contenido del apartado. TEXTO ORIGINAL A ADAPTAR: """ Texto """ | I15: 1. Instrucciones generales - Actúa como un experto adaptador de textos a Lectura Fácil. - Tu tarea es transformar el texto original proporcionado respetando estrictamente el sentido y el carácter del original. - Debes conservar la información relevante sin incluir opiniones personales o sesgos. - No incluyas explicaciones sobre los cambios aplicados en la simplificación; genera únicamente el texto adaptado y estructurado. 2. Objetivo general - El documento resultante debe estar destinado a personas con dificultades de comprensión lectora, como personas con discapacidad intelectual, personas mayores o personas que no dominan el idioma. - Si el texto aborda la protección de datos, el objetivo primordial es facilitar que el usuario comprenda sus derechos, sepa cómo decidir sobre el uso de sus datos y entienda cómo estos deben protegerse. 3. Signos de puntuación y símbolos - No debes escribir palabras ni frases con todas sus letras en mayúsculas, excepto cuando se trate de siglas. - Debes utilizar el punto y aparte para separar frases u oraciones que presenten ideas diferentes. - Las ideas enlazadas se deberían separar mediante un punto en lugar de una coma. EJEMPLO: Incorrecto: Como ayer estaba lloviendo, Juan cogió el paraguas. Correcto: Ayer estaba lloviendo. Por eso, Juan cogió el paraguas. - No se debe utilizar el punto y coma (;). - No se debe utilizar etcétera, ni los puntos suspensivos (...). Se puede sustituir por entre otros, y muchos más y otras frases similares. - Se deberían utilizar los dos puntos (:) cuando se introduce una lista que enumera más de tres elementos. 4. Formato de línea - Se debe presentar una sola idea principal por línea o bloque. - No deberían dividirse los sintagmas al cambiar de línea; las palabras accesorias (artículos, preposiciones) que queden al final de una línea deberían pasar al inicio de la siguiente. EJEMPLO: Incorrecto: Juan tiene un coche de color rojo. Correcto: Juan tiene un coche de color rojo. Correcto: Juan tiene un coche de color rojo. - Siempre que sea posible, si hay varios elementos (como una enumeración de derechos o tareas), se debe utilizar un listado hacia abajo. 5. Léxico - Se debe utilizar un lenguaje sencillo, claro y de uso frecuente. - Se deben evitar los adverbios terminados en "-mente". EJEMPLO: Incorrecto: Él habla claramente. Correcto: Él habla muy claro. - Se deben evitar los superlativos y sustituirlos añadiendo el adverbio "muy" al adjetivo. - Se debe utilizar a lo largo del texto la misma palabra para denominar el mismo objeto, derecho o referente. - Glosas: Debería usarse una glosa (explicación) cuando sea necesario incluir palabras técnicas o complejas. La palabra a definir debe ir en negrita, seguida de una explicación sencilla en la siguiente línea y, si es posible, un ejemplo de uso. La glosa debe usarse la primera vez que aparece la palabra o expresión que explica. 6. Números - Se deberían escribir los números en cifra. - Se debería evitar el uso de números ordinales y sustituirlos por números cardinales (ej. planta número 18 en vez de decimoctava). - Se debería evitar el uso de fracciones y porcentajes y sustituirlos por descripciones cualitativas. EJEMPLO: Incorrecto: El 25% de la población. Correcto: Una de cada cuatro personas. - Se debería escribir la fecha completa (ej. 12 de abril de 2020) y evitar guiones o barras. 7. Morfosintaxis - Se deberían utilizar frases sencillas y evitar oraciones complejas o subordinadas excesivas. - Se debería utilizar el presente de indicativo siempre que sea posible. - Se debe evitar el uso de la voz pasiva y la pasiva refleja. EJEMPLO VOZ PASIVA: Incorrecto: El martillo es usado por Juan en su trabajo. Correcto: Juan usa el martillo en su trabajo. EJEMPLO PASIVA REFLEJA: Incorrecto: Se venden casas. Correcto: Vendemos casas. - Se debería evitar en lo posible el uso de oraciones con gerundio. - Se deberían usar preferentemente oraciones afirmativas. En caso de necesitar una negación, la oración debe ser clara y evitar la doble negación. - El texto debería dirigirse directamente al lector siempre que sea posible y requiera o explicite una actuación del mismo. EJEMPLO: Incorrecto: Meter el pollo en el horno a 180°. Correcto: Mete el pollo en el horno a 180 grados. 8. Estructura de la información - Se debe mantener la cohesión y coherencia del texto a lo largo de todo el documento. - Se debería agrupar la información sobre un mismo tema en bloques de texto separados. - La redacción de los títulos debería hacer referencia o anticipar la información del contenido del apartado. TEXTO ORIGINAL A ADAPTAR: """ Texto """ | J15: 1. Instrucciones generales - Actúa como un experto adaptador de textos a Lectura Fácil. - Tu tarea es transformar el texto original proporcionado respetando estrictamente el sentido y el carácter del original. - Debes conservar la información relevante sin incluir opiniones personales o sesgos. - No incluyas explicaciones sobre los cambios aplicados en la simplificación; genera únicamente el texto adaptado y estructurado. 2. Objetivo general - El documento resultante debe estar destinado a personas con dificultades de comprensión lectora, como personas con discapacidad intelectual, personas mayores o personas que no dominan el idioma. - Si el texto aborda la protección de datos, el objetivo primordial es facilitar que el usuario comprenda sus derechos, sepa cómo decidir sobre el uso de sus datos y entienda cómo estos deben protegerse. 3. Signos de puntuación y símbolos - No debes escribir palabras ni frases con todas sus letras en mayúsculas, excepto cuando se trate de siglas. - Debes utilizar el punto y aparte para separar frases u oraciones que presenten ideas diferentes. - Las ideas enlazadas se deberían separar mediante un punto en lugar de una coma. EJEMPLO: Incorrecto: Como ayer estaba lloviendo, Juan cogió el paraguas. Correcto: Ayer estaba lloviendo. Por eso, Juan cogió el paraguas. - No se debe utilizar el punto y coma (;). - No se debe utilizar etcétera, ni los puntos suspensivos (...). Se puede sustituir por entre otros, y muchos más y otras frases similares. - Se deberían utilizar los dos puntos (:) cuando se introduce una lista que enumera más de tres elementos. 4. Formato de línea - Se debe presentar una sola idea principal por línea o bloque. - No deberían dividirse los sintagmas al cambiar de línea; las palabras accesorias (artículos, preposiciones) que queden al final de una línea deberían pasar al inicio de la siguiente. EJEMPLO: Incorrecto: Juan tiene un coche de color rojo. Correcto: Juan tiene un coche de color rojo. Correcto: Juan tiene un coche de color rojo. - Siempre que sea posible, si hay varios elementos (como una enumeración de derechos o tareas), se debe utilizar un listado hacia abajo. 5. Léxico - Se debe utilizar un lenguaje sencillo, claro y de uso frecuente. - Se deben evitar los adverbios terminados en "-mente". EJEMPLO: Incorrecto: Él habla claramente. Correcto: Él habla muy claro. - Se deben evitar los superlativos y sustituirlos añadiendo el adverbio "muy" al adjetivo. - Se debe utilizar a lo largo del texto la misma palabra para denominar el mismo objeto, derecho o referente. - Glosas: Debería usarse una glosa (explicación) cuando sea necesario incluir palabras técnicas o complejas. La palabra a definir debe ir en negrita, seguida de una explicación sencilla en la siguiente línea y, si es posible, un ejemplo de uso. La glosa debe usarse la primera vez que aparece la palabra o expresión que explica. 6. Números - Se deberían escribir los números en cifra. - Se debería evitar el uso de números ordinales y sustituirlos por números cardinales (ej. planta número 18 en vez de decimoctava). - Se debería evitar el uso de fracciones y porcentajes y sustituirlos por descripciones cualitativas. EJEMPLO: Incorrecto: El 25% de la población. Correcto: Una de cada cuatro personas. - Se debería escribir la fecha completa (ej. 12 de abril de 2020) y evitar guiones o barras. 7. Morfosintaxis - Se deberían utilizar frases sencillas y evitar oraciones complejas o subordinadas excesivas. - Se debería utilizar el presente de indicativo siempre que sea posible. - Se debe evitar el uso de la voz pasiva y la pasiva refleja. EJEMPLO VOZ PASIVA: Incorrecto: El martillo es usado por Juan en su trabajo. Correcto: Juan usa el martillo en su trabajo. EJEMPLO PASIVA REFLEJA: Incorrecto: Se venden casas. Correcto: Vendemos casas. - Se debería evitar en lo posible el uso de oraciones con gerundio. - Se deberían usar preferentemente oraciones afirmativas. En caso de necesitar una negación, la oración debe ser clara y evitar la doble negación. - El texto debería dirigirse directamente al lector siempre que sea posible y requiera o explicite una actuación del mismo. EJEMPLO: Incorrecto: Meter el pollo en el horno a 180°. Correcto: Mete el pollo en el horno a 180 grados. 8. Estructura de la información - Se debe mantener la cohesión y coherencia del texto a lo largo de todo el documento. - Se debería agrupar la información sobre un mismo tema en bloques de texto separados. - La redacción de los títulos debería hacer referencia o anticipar la información del contenido del apartado. TEXTO ORIGINAL A ADAPTAR: """ Texto """ | K15: 1. Instrucciones generales - Actúa como un experto adaptador de textos a Lectura Fácil. - Tu tarea es transformar el texto original proporcionado respetando estrictamente el sentido y el carácter del original. - Debes conservar la información relevante sin incluir opiniones personales o sesgos. - No incluyas explicaciones sobre los cambios aplicados en la simplificación; genera únicamente el texto adaptado y estructurado. 2. Objetivo general - El documento resultante debe estar destinado a personas con dificultades de comprensión lectora, como personas con discapacidad intelectual, personas mayores o personas que no dominan el idioma. - Si el texto aborda la protección de datos, el objetivo primordial es facilitar que el usuario comprenda sus derechos, sepa cómo decidir sobre el uso de sus datos y entienda cómo estos deben protegerse. 3. Signos de puntuación y símbolos - No debes escribir palabras ni frases con todas sus letras en mayúsculas, excepto cuando se trate de siglas. - Debes utilizar el punto y aparte para separar frases u oraciones que presenten ideas diferentes. - Las ideas enlazadas se deberían separar mediante un punto en lugar de una coma. EJEMPLO: Incorrecto: Como ayer estaba lloviendo, Juan cogió el paraguas. Correcto: Ayer estaba lloviendo. Por eso, Juan cogió el paraguas. - No se debe utilizar el punto y coma (;). - No se debe utilizar etcétera, ni los puntos suspensivos (...). Se puede sustituir por entre otros, y muchos más y otras frases similares. - Se deberían utilizar los dos puntos (:) cuando se introduce una lista que enumera más de tres elementos. 4. Formato de línea - Se debe presentar una sola idea principal por línea o bloque. - No deberían dividirse los sintagmas al cambiar de línea; las palabras accesorias (artículos, preposiciones) que queden al final de una línea deberían pasar al inicio de la siguiente. EJEMPLO: Incorrecto: Juan tiene un coche de color rojo. Correcto: Juan tiene un coche de color rojo. Correcto: Juan tiene un coche de color rojo. - Siempre que sea posible, si hay varios elementos (como una enumeración de derechos o tareas), se debe utilizar un listado hacia abajo. 5. Léxico - Se debe utilizar un lenguaje sencillo, claro y de uso frecuente. - Se deben evitar los adverbios terminados en "-mente". EJEMPLO: Incorrecto: Él habla claramente. Correcto: Él habla muy claro. - Se deben evitar los superlativos y sustituirlos añadiendo el adverbio "muy" al adjetivo. - Se debe utilizar a lo largo del texto la misma palabra para denominar el mismo objeto, derecho o referente. - Glosas: Debería usarse una glosa (explicación) cuando sea necesario incluir palabras técnicas o complejas. La palabra a definir debe ir en negrita, seguida de una explicación sencilla en la siguiente línea y, si es posible, un ejemplo de uso. La glosa debe usarse la primera vez que aparece la palabra o expresión que explica. 6. Números - Se deberían escribir los números en cifra. - Se debería evitar el uso de números ordinales y sustituirlos por números cardinales (ej. planta número 18 en vez de decimoctava). - Se debería evitar el uso de fracciones y porcentajes y sustituirlos por descripciones cualitativas. EJEMPLO: Incorrecto: El 25% de la población. Correcto: Una de cada cuatro personas. - Se debería escribir la fecha completa (ej. 12 de abril de 2020) y evitar guiones o barras. 7. Morfosintaxis - Se deberían utilizar frases sencillas y evitar oraciones complejas o subordinadas excesivas. - Se debería utilizar el presente de indicativo siempre que sea posible. - Se debe evitar el uso de la voz pasiva y la pasiva refleja. EJEMPLO VOZ PASIVA: Incorrecto: El martillo es usado por Juan en su trabajo. Correcto: Juan usa el martillo en su trabajo. EJEMPLO PASIVA REFLEJA: Incorrecto: Se venden casas. Correcto: Vendemos casas. - Se debería evitar en lo posible el uso de oraciones con gerundio. - Se deberían usar preferentemente oraciones afirmativas. En caso de necesitar una negación, la oración debe ser clara y evitar la doble negación. - El texto debería dirigirse directamente al lector siempre que sea posible y requiera o explicite una actuación del mismo. EJEMPLO: Incorrecto: Meter el pollo en el horno a 180°. Correcto: Mete el pollo en el horno a 180 grados. 8. Estructura de la información - Se debe mantener la cohesión y coherencia del texto a lo largo de todo el documento. - Se debería agrupar la información sobre un mismo tema en bloques de texto separados. - La redacción de los títulos debería hacer referencia o anticipar la información del contenido del apartado. TEXTO ORIGINAL A ADAPTAR: """ Texto """ | N15: adapta el siguiente texto a lectura fácil:
F16: Rol Actúo como: Corrector de textos Especialista en lectura fácil Adaptador de contenido para accesibilidad cognitiva Objetivo Transformar textos para que sean: Claros Simples Fáciles de entender Visualmente accesibles Reglas clave que aplico 1. Frases Máximo 15 palabras Una idea por frase Orden: Sujeto + Verbo + Complemento Uso presente y voz activa 2. Lenguaje Palabras comunes y concretas Evito: tecnicismos metáforas sinónimos innecesarios Uso un término por concepto 3. Estructura Títulos claros Listas con viñetas Información separada por bloques Nada de párrafos largos 4. Formato visual Negrita → ideas clave Subrayado → información importante Texto alineado a la izquierda Espacios entre bloques 5. Contenido adicional Siempre añado: Glosario (5 palabras difíciles) 5 ideas clave Resumen final en mayúsculas Plantilla que puedes usar (muy útil) Si quieres replicarlo, puedes usar algo como esto: Actúa como un experto en lectura fácil. Adapta el texto para que cumpla estas reglas: - Frases de máximo 15 palabras - Una idea por frase - Lenguaje simple y cotidiano - Sin tecnicismos ni metáforas - Estructura clara con títulos y listas Formato: - Usa negrita para ideas clave - Usa subrayado para información importante - Añade: - Glosario (5 términos) - 5 ideas clave - Resumen final en mayúsculas Mantén el significado original. | G16: 🧠 Cómo estoy configurado en esta tarea Estoy configurado como un asistente especializado en: 📄 Lectura fácil Mi objetivo es transformar textos complejos en: Frases cortas Una idea por frase Lenguaje sencillo Sin tecnicismos innecesarios Orden claro Explicaciones de palabras difíciles Estructura muy visual 🎯 Reglas principales que sigo Cuando adapto un texto: 1. Simplifico el lenguaje Evito palabras jurídicas complejas Evito frases largas Sustituyo términos técnicos por explicaciones simples 2. Divido las ideas Cada frase tiene una sola idea Uso muchos apartados y títulos 3. Hago el texto más fácil de entender Reescribo la información importante Elimino repeticiones Mantengo el sentido legal básico 4. Mantengo el contenido legal esencial Derechos Obligaciones Protección de datos Autorizaciones 5. Evito Lenguaje académico Frases pasivas complejas Estructuras legales largas Abreviaturas sin explicar 📌 Importante Aunque el texto cambia mucho, intento que: No se pierda la información legal importante El contenido siga siendo fiel al original Sea más fácil de leer para personas con dificultades cognitivas

Sheet Hoja1
A1: AdaptaTuTexto (Gemini 3.1 Pro) Muy A2 | B1: AdaptaTuTexto (Gemini 3.1 Pro) Facil B1 | C1: AdaptaTuTexto (Gemini 3.1 Pro) Sencillo B2 | D1: AdaptaTuTexto (deepseek-v3.2) Muy A2 | E1: AdaptaTuTexto (deepseek-v3.2) Facil B1 | F1: AdaptaTuTexto (deepseek-v3.2) Sencillo B2
A2: =#REF! -> #REF! | B2: =#REF! -> #REF! | C2: =#REF! -> #REF! | D2: =#REF! -> #REF! | E2: =#REF! -> #REF! | F2: =#REF! -> #REF!
A3: =IF(A2>='Matriz comparativa'!#REF!,"Cumple", "No cumple") -> #REF! | B3: =IF(B2>='Matriz comparativa'!#REF!,"Cumple", "No cumple") -> #REF! | C3: =IF(C2>='Matriz comparativa'!#REF!,"Cumple", "No cumple") -> #REF! | D3: =IF(D2>='Matriz comparativa'!#REF!,"Cumple", "No cumple") -> #REF! | E3: =IF(E2>='Matriz comparativa'!#REF!,"Cumple", "No cumple") -> #REF! | F3: =IF(F2>='Matriz comparativa'!#REF!,"Cumple", "No cumple") -> #REF!
A4: Información sobre sus datos. | B4: Información sobre el cuidado de sus datos. | C4: Información sobre la protección de sus datos
B5: El Grupo de Ingeniería Ontológica es el responsable de este trabajo.
A6: usa los datos | B6: La Universidad Politécnica de Madrid usará la información para investigar. | C6: El Grupo de Ingeniería Ontológica utilizará estos datos para investigar.
A7: usa los datos para un estudio. | B7: usemos sus datos. | C7: use su información
A9: Usted puede ver sus datos. Usted puede cambiar o borrar sus datos. Hay más información en esta página web: https://oeg.fi.upm.es/protecciondatos.html | B9: Usted tiene derecho a ver, cambiar o borrar sus datos. También puede leer más información en una página de internet. La dirección es oeg.fi.upm.es/protecciondatos.html. | C9: Usted tiene derecho a ver, corregir o borrar sus datos personales. Puede encontrar más información en esta página web: https://oeg.fi.upm.es/protecciondatos.html
A11: Gemini 3.1 Pro | B11: Gemini 3.1 Pro | C11: Gemini 3.1 Pro | D11: deepseek-v3.2 | E11: deepseek-v3.3 | F11: deepseek-v3.4
A12: 23 | B12: 24 | C12: 22 | D12: 29 | E12: 33 | F12: 30
A13: 1 | B13: 1 | C13: 1 | D13: 1 | E13: 1 | F13: 1
A14: Información sobre sus datos. Esta encuesta es secreta. Nadie sabe quién responde. Cumplimos las leyes de datos. Explicamos cómo usamos su información. Si usted responde, da su permiso. La Universidad Politécnica de Madrid usa sus datos. La Universidad usa los datos para un estudio. Usted puede ver sus datos. Usted puede cambiar o borrar sus datos. Hay más información en esta página web: https://oeg.fi.upm.es/protecciondatos.html | B14: Información sobre el cuidado de sus datos. Esta encuesta es anónima. Nadie sabrá quién ha respondido a las preguntas. Queremos explicarle cómo cuidamos su información personal. Cumplimos las leyes de protección de datos (normas para cuidar su información). Al rellenar la encuesta, usted acepta que usemos sus datos. La Universidad Politécnica de Madrid usará la información para investigar. El Grupo de Ingeniería Ontológica es el responsable de este trabajo. Usted tiene derecho a ver, cambiar o borrar sus datos. También puede leer más información en una página de internet. La dirección es oeg.fi.upm.es/protecciondatos.html. | C14: Información sobre la protección de sus datos Este cuestionario es anónimo. Por tanto, no guardamos su nombre ni sus datos personales. Cumplimos con las leyes actuales de privacidad. Si rellena las preguntas, acepta que la Universidad Politécnica de Madrid use su información. El Grupo de Ingeniería Ontológica utilizará estos datos para investigar. Usted tiene derecho a ver, corregir o borrar sus datos personales. Puede encontrar más información en esta página web: https://oeg.fi.upm.es/protecciondatos.html
A16: Cada linea de texto tiene una separación adicional. Ejemplo: oración 1 oración 2

Sheet Check-list
A1: Categoría | B1: Epígrafe | C1: Item de Validación | D1: Cumple (SÍ/NO) | E1: Observaciones | F1: Pesos | G1: Detalle de la Validación
A2: Básica (Primera Capa) | B2: Título | F2: 1 | G2: Información sobre protección de datos
A3: Básica (Primera Capa) | B3: Responsable | F3: 1 | G3: por la Universidad Politécnica de Madrid (Grupo de Ingeniería Ontológica), responsable de este tratamiento,
A4: Básica (Primera Capa) | B4: Finalidad | F4: 1 | G4: finalidad relacionada con la investigación ya señalada.
A5: Básica (Primera Capa) | B5: Legitimación | F5: 1 | G5: que tus datos sean tratados
A6: Básica (Primera Capa) | B6: Destinatarios | F6: 1
A7: Básica (Primera Capa) | B7: Derechos | F7: 1 | G7: También te informamos de que puedes acceder, rectificar y suprimir los datos, así como ejercer otros derechos, en los términos que se indican en la información adicional, disponible en el siguiente enlace: "https://oeg.fi.upm.es/protecciondatos.html".
C9: Total Cumplidos | F9: =SUM(F2:F8) -> 6

Sheet 1
A1: Categoría | B1: Epígrafe | C1: Ítem de Validación | D1: Cumple (SÍ/NO) | E1: Observaciones | F1: Evidencia
A2: Básica (Primera Capa) | B2: Título | C2: Identificación clara del bloque informativo. | D2: 1 | E2: El texto comienza con un título inequívoco que delimita la naturaleza de la información. | F2: "Información sobre protección de datos"
A3: Básica (Primera Capa) | B3: Responsable | C3: Identidad de la entidad que trata los datos. | D3: 1 | E3: Identifica claramente a la persona jurídica (UPM) y al grupo específico encargado del tratamiento. | F3: "Universidad Politécnica de Madrid (Grupo de Ingeniería Ontológica), responsable de este tratamiento,"
A4: Básica (Primera Capa) | B4: Finalidad | C4: Descripción de los fines del tratamiento. | D4: 0.5 | E4: Riesgo Medio. Menciona que es para "investigación", pero es una fórmula genérica. No especifica el objeto concreto de la investigación, lo que debilita el principio de limitación de la finalidad. | F4: "con la finalidad relacionada con la investigación ya señalada."
A5: Básica (Primera Capa) | B5: Legitimación | C5: Base jurídica aplicable al tratamiento. | D5: 1 | E5: Se determina de forma explícita que la base legal es el consentimiento del interesado al rellenar el formulario. | F5: "te informamos de que consientes que tus datos sean tratados"
A6: Básica (Primera Capa) | B6: Destinatarios | C6: Previsión de cesiones o transferencias. | D6: 0 | E6: Riesgo Alto. Omisión absoluta. La guía AEPD exige que este epígrafe aparezca siempre en la primera capa, incluso para indicar que no se prevén cesiones (ej. "No se cederán datos a terceros, salvo obligación legal"). | F6: Ninguna (Ausencia total de texto).
A7: Básica (Primera Capa) | B7: Derechos | C7: Enlace e indicación para ejercer los derechos y acceder a la 2ª capa. | D7: 1 | E7: SÍ | F7: "puedes acceder, rectificar y suprimir los datos, así como ejercer otros derechos... disponible en el siguiente enlace: 'https://oeg.fi.upm.es/protecciondatos.html'."
C9: Total Cumplidos | D9: =SUM(D2:D7) -> 4.5 | F9: =SUM(F2:F8) -> 0

Sheet 2
A1: Categoría | B1: Epígrafe | C1: Ítem de Validación | D1: Cumple | E1: Observaciones | F1: Evidencia
A2: Básica (Primera Capa) | B2: Título | C2: Identificación clara del bloque informativo. | D2: 1 | E2: El texto cuenta con un encabezado explícito que delimita claramente el inicio de la cláusula de privacidad. | F2: "Información sobre protección de datos"
A3: Básica (Primera Capa) | B3: Responsable | C3: Identidad de la entidad que trata los datos. | D3: 1 | E3: Se identifica de forma inequívoca a la persona jurídica y al grupo de investigación concreto que ejerce el control. | F3: "Universidad Politécnica de Madrid (Grupo de Ingeniería Ontológica), responsable de este tratamiento"
A4: Básica (Primera Capa) | B4: Finalidad | C4: Descripción de los fines del tratamiento. | D4: 0.5 | E4: Riesgo Medio. El texto remite a una "investigación ya señalada". Si la cláusula se lee de forma aislada, el fin específico no es autónomo, explícito ni conciso por sí mismo dentro de la capa. | F4: "con la finalidad relacionada con la investigación ya señalada."
A5: Básica (Primera Capa) | B5: Legitimación | C5: Base jurídica aplicable al tratamiento. | D5: 1 | E5: Identifica explícitamente el consentimiento del interesado mediante una acción afirmativa (cumplimentar el cuestionario). | F5: "te informamos de que consientes que tus datos sean tratados"
A6: Básica (Primera Capa) | B6: Destinatarios | C6: Previsión de cesiones o transferencias. | D6: 0 | E6: Riesgo Alto. Omisión total. La guía de la AEPD establece que este epígrafe debe aparecer siempre en la primera capa, aun cuando no se prevean comunicaciones a terceros. | F6: Ninguna (Ausencia total de mención en el texto)
A7: Básica (Primera Capa) | B7: Derechos | C7: Enlace e indicación para ejercer los derechos y acceder a la 2ª capa. | D7: 1 | E7: Menciona derechos básicos (acceso, rectificación, supresión), alude a otros adicionales e incluye el hipervínculo directo para la información detallada. | F7: "puedes acceder, rectificar y suprimir los datos, así como ejercer otros derechos... disponible en el siguiente enlace: 'https://oeg.fi.upm.es/protecciondatos.html'."
C9: Total Cumplidos | D9: =SUM(D2:D7) -> 4.5 | F9: =SUM(F2:F8) -> 0

Sheet 3
A1: Categoría | B1: Epígrafe | C1: Ítem de Validación | D1: Cumple | E1: Observaciones | F1: Evidencia
A2: Básica (Primera Capa) | B2: Título | C2: Identificación clara del bloque informativo. | D2: 1 | E2: El texto inicia con un encabezado explícito que delimita el inicio de la información de protección de datos. | F2: "INFORMACIÓN SOBRE PROTECCIÓN DE DATOS"
A3: Básica (Primera Capa) | B3: Responsable | C3: Identidad de la entidad que trata los datos. | D3: 1 | E3: Se identifica claramente a la institución académica y al grupo de investigación concreto que trata los datos. | F3: "Universidad Politécnica de Madrid (Grupo de Ingeniería Ontológica)"
A4: Básica (Primera Capa) | B4: Finalidad | C4: Descripción de los fines del tratamiento. | D4: 0.5 | E4: Riesgo Medio. El texto indica que es para una "investigación que hemos mencionado". El fin específico no es autónomo ni autosuficiente por sí mismo dentro de la capa informativa si se lee de forma aislada. | F4: "Esto es para la investigación que hemos mencionado."
A5: Básica (Primera Capa) | B5: Legitimación | C5: Base jurídica aplicable al tratamiento. | D5: 1 | E5: Cumple semánticamente al adaptar el concepto a lectura fácil, identificando el consentimiento mediante la acción afirmativa de responder. | F5: "Si decides responder el cuestionario, aceptas que..."
A6: Básica (Primera Capa) | B6: Destinatarios | C6: Previsión de cesiones o transferencias. | D6: 0 | E6: Riesgo Alto. Omisión absoluta. La guía de la AEPD exige que este epígrafe aparezca siempre en la primera capa, incluso para manifestar que no se prevén comunicaciones a terceros. | F6: Ninguna (Ausencia total de texto)
A7: Básica (Primera Capa) | B7: Derechos | C7: Enlace e indicación para ejercer los derechos y acceder a la 2ª capa. | D7: 1 | E7: Traduce adecuadamente a lectura fácil los derechos de acceso, rectificación y supresión ("cambiar y borrar"), nombra la existencia de otros y aporta el hipervínculo directo. | F7: "También puedes acceder, cambiar y borrar tus datos. Tienes otros derechos que puedes ejercer. Para más información, puedes visitar este enlace: 'https://oeg.fi.upm.es/protecciondatos.html'."
C9: Total Cumplidos | D9: =SUM(D2:D7) -> 4.5 | F9: =SUM(F2:F8) -> 0

Sheet 4
A1: Categoría | B1: Epígrafe | C1: Ítem de Validación | D1: Cumple | E1: Observaciones | F1: Evidencia
A2: Básica (Primera Capa) | B2: Título | C2: Identificación clara del bloque informativo. | D2: 1 | E2: El texto cuenta con un encabezado explícito que delimita claramente el inicio de la cláusula informativa. | F2: "Información sobre protección de datos"
A3: Básica (Primera Capa) | B3: Responsable | C3: Identidad de la entidad que trata los datos. | D3: 1 | E3: Se identifica de forma inequívoca a la persona jurídica y al grupo de investigación que ejerce el control. | F3: "La Universidad Politécnica de Madrid usa tus datos para una investigación. El grupo responsable es el Grupo de Ingeniería Ontológica."
A4: Básica (Primera Capa) | B4: Finalidad | C4: Descripción de los fines del tratamiento. | D4: 0.5 | E4: Riesgo Medio. El texto indica de forma genérica que es para "una investigación". Al no especificar el objeto ni el área temática del estudio dentro del texto, la finalidad carece de la concreción exigida para ser considerada plenamente explícita y legítima. | F4: "usa tus datos para una investigación." / "para esta investigación."
A5: Básica (Primera Capa) | B5: Legitimación | C5: Base jurídica aplicable al tratamiento. | D5: 1 | E5: Cumple semánticamente al adaptar el concepto a lectura fácil, asociando la base legal (consentimiento) a la acción afirmativa de completar el cuestionario. | F5: "Si completas el cuestionario, aceptas el uso de tus datos..."
A6: Básica (Primera Capa) | B6: Destinatarios | C6: Previsión de cesiones o transferencias. | D6: 0 | E6: Riesgo Alto. Omisión absoluta. La guía de la AEPD establece que este epígrafe debe figurar siempre en la primera capa informativa, inclusive para manifestar que no se prevén comunicaciones de datos a terceros. | F6: Ninguna (Ausencia total de mención en el texto)
A7: Básica (Primera Capa) | B7: Derechos | C7: Enlace e indicación para ejercer los derechos y acceder a la 2ª capa. | D7: 1 | E7: Adapta correctamente los derechos principales a lectura fácil (acceso = "Ver", rectificación = "Cambiar", supresión = "Pedir que eliminen"), menciona la existencia de otros y proporciona el hipervínculo directo. | F7: "Tú puedes: Ver tus datos. Cambiar tus datos. Pedir que eliminen tus datos. Usar otros derechos... Puedes leer más información en este enlace: https://oeg.fi.upm.es/protecciondatos.html"
C9: Total Cumplidos | D9: =SUM(D2:D7) -> 4.5

Sheet 5
A1: Categoría | B1: Epígrafe | C1: Ítem de Validación | D1: Cumple | E1: Observaciones | F1: Evidencia
A2: Básica (Primera Capa) | B2: Título | C2: Identificación clara del bloque informativo. | D2: 1 | E2: El texto cuenta con un encabezado explícito que delimita el inicio de la información. | F2: "Información sobre protección de datos"
A3: Básica (Primera Capa) | B3: Responsable | C3: Identidad de la entidad que trata los datos. | D3: 0.5 | E3: Riesgo Bajo. Identifica la persona jurídica (UPM), pero a diferencia de los textos anteriores, ha omitido la mención al "Grupo de Ingeniería Ontológica" que concreta el departamento encargado. | F3: "La responsable del tratamiento de los datos es la Universidad Politécnica de Madrid."
A4: Básica (Primera Capa) | B4: Finalidad | C4: Descripción de los fines del tratamiento. | D4: 0.5 | E4: Riesgo Medio. Se indica de forma genérica que es para "una investigación". Al no especificar el objeto ni el área temática del estudio dentro de la capa, la finalidad carece de la concreción exigida para ser considerada plenamente explícita. | F4: "La información que se escriba se usará para una investigación." / "para esta investigación."
A5: Básica (Primera Capa) | B5: Legitimación | C5: Base jurídica aplicable al tratamiento. | D5: 1 | E5: Cumple semánticamente adaptando el concepto a lectura fácil, asociando el consentimiento a la acción afirmativa de completar el cuestionario. | F5: "Si completas el cuestionario, aceptas que tus datos se usen..."
A6: Básica (Primera Capa) | B6: Destinatarios | C6: Previsión de cesiones o transferencias. | D6: 0 | E6: Riesgo Alto. Omisión absoluta. La guía de la AEPD establece que este epígrafe debe figurar siempre en la primera capa, inclusive para manifestar que no se prevén comunicaciones de datos a terceros. | F6: Ninguna (Ausencia total de mención en el texto)
A7: Básica (Primera Capa) | B7: Derechos | C7: Enlace e indicación para ejercer los derechos y acceder a la 2ª capa. | D7: 0.5 | E7: Riesgo Alto. Aunque adapta correctamente los derechos principales a lectura fácil, no incluye un enlace web válido (URL), hipervínculo o indicación textual física accesible para consultar la segunda capa. | F7: "Puedes: Consultar tus datos. Cambiar tus datos. Pedir que se eliminen tus datos. Ejercer otros derechos... Puedes leer más información aquí: Protección de datos UPM"
C9: Total Cumplidos | D9: =SUM(D2:D7) -> 3.5

Sheet 6
A1: Categoría | B1: Epígrafe | C1: Ítem de Validación | D1: Cumple | E1: Observaciones | F1: Evidencia
A2: Básica (Primera Capa) | B2: Título | C2: Identificación clara del bloque informativo. | D2: 1 | E2: El texto cuenta con un encabezado inequívoco y visible que identifica el bloque informativo. | F2: "Información sobre la protección de tus datos"
A3: Básica (Primera Capa) | B3: Responsable | C3: Identidad de la entidad que trata los datos. | D3: 1 | E3: Identifica a la persona jurídica (UPM) y al grupo investigador concreto como responsable técnico. | F3: "La Universidad Politécnica de Madrid usa tus datos... El Grupo de Ingeniería Ontológica es el responsable de tus datos."
A4: Básica (Primera Capa) | B4: Finalidad | C4: Descripción de los fines del tratamiento. | D4: 0.5 | E4: Riesgo Medio. Se determina que el fin es "investigar". Al ser adaptado a lectura fácil es comprensible, pero sigue siendo un fin indeterminado (vago) al no acotar el proyecto, área o el objeto de estudio específico dentro del texto. | F4: "Esta universidad usa tus datos para investigar."
A5: Básica (Primera Capa) | B5: Legitimación | C5: Base jurídica aplicable al tratamiento. | D5: 1 | E5: Se valida positivamente la adaptación a lectura fácil. Traduce el concepto "consentimiento" ligándolo directamente a una acción afirmativa y voluntaria del usuario. | F5: "Tú decides responder las preguntas. Con esta acción tú das permiso para usar tus datos."
A6: Básica (Primera Capa) | B6: Destinatarios | C6: Previsión de cesiones o transferencias. | D6: 0 | E6: Riesgo Alto. Omisión absoluta. La guía de la AEPD exige de forma expresa que este epígrafe figure siempre en la primera capa, incluso para clarificar que no se prevén comunicaciones de datos a terceros. | F6: Ninguna (Ausencia total de mención en el texto)
A7: Básica (Primera Capa) | B7: Derechos | C7: Enlace e indicación para ejercer los derechos y acceder a la 2ª capa. | D7: 1 | E7: Cumple de manera notable. Desglosa los derechos principales de forma muy accesible y aporta la dirección URL exacta y operativa para acceder a la segunda capa. | F7: "Tú puedes pedir estas cuatro acciones: Ver tus datos. Cambiar tus datos. Borrar tus datos. Pedir otros derechos... Tú puedes encontrar la información en esta página web: https://oeg.fi.upm.es/protecciondatos.html"
C9: Total Cumplidos | D9: =SUM(D2:D7) -> 4.5

Sheet 7
A1: Categoría | B1: Epígrafe | C1: Ítem de Validación | D1: Cumple | E1: Observaciones | F1: Evidencia
A2: Básica (Primera Capa) | B2: Título | C2: Identificación clara del bloque informativo. | D2: 1 | E2: El texto cuenta con un encabezado inicial explícito que delimita claramente el bloque informativo de protección de datos. | F2: "Información sobre tus datos"
A3: Básica (Primera Capa) | B3: Responsable | C3: Identidad de la entidad que trata los datos. | D3: 1 | E3: Identifica de manera inequívoca tanto a la persona jurídica como al grupo específico encargado del tratamiento de la información. | F3: "La Universidad Politécnica de Madrid. Grupo de Ingeniería Ontológica. Es la responsable del uso de tus datos."
A4: Básica (Primera Capa) | B4: Finalidad | C4: Descripción de los fines del tratamiento. | D4: 0.5 | E4: Nivel de riesgo: Medio. Aunque se adapta semánticamente a lectura fácil, la cláusula remite a una "investigación indicada antes". Si un usuario lee este bloque de forma aislada, el fin exacto no es autónomo, explícito ni determinado dentro de la propia capa. | F4: "La finalidad es la investigación indicada antes en este cuestionario."
A5: Básica (Primera Capa) | B5: Legitimación | C5: Base jurídica aplicable al tratamiento. | D5: 1 | E5: Cumple semánticamente con las pautas de accesibilidad y claridad (lectura fácil). Vincula el consentimiento a una acción afirmativa y voluntaria del interesado. | F5: "Si decides rellenar el cuestionario, aceptas que la Universidad Politécnica de Madrid use tus datos."
A6: Básica (Primera Capa) | B6: Destinatarios | C6: Previsión de cesiones o transferencias. | D6: 0 | E6: Nivel de riesgo: Alto. Omisión absoluta. La guía de la AEPD exige de forma expresa que este epígrafe figure siempre en la primera capa, inclusive para manifestar que no se prevén comunicaciones de datos a terceros. | F6: Ninguna (Ausencia total de mención en el texto)
A7: Básica (Primera Capa) | B7: Derechos | C7: Enlace e indicación para ejercer los derechos y acceder a la 2ª capa. | D7: 1 | E7: Cumple de manera notable. Desglosa los derechos principales de forma clara, incluye definiciones pedagógicas breves y proporciona un enlace URL directo y operativo hacia la segunda capa. | F7: "Tú puedes hacer lo siguiente con tus datos: Acceder a tus datos... Puedes leer la información adicional en este enlace: https://oeg.fi.upm.es/protecciondatos.html"
C9: Total Cumplidos | D9: =SUM(D2:D7) -> 4.5

Sheet 8
A1: Categoría | B1: Epígrafe | C1: Ítem de Validación | D1: Cumple | E1: Observaciones | F1: Evidencia
A2: Básica (Primera Capa) | B2: Título | C2: Identificación clara del bloque informativo. | D2: 1 | E2: El texto cuenta con un encabezado inicial explícito que delimita perfectamente el bloque informativo. | F2: "Protección de tus datos personales"
A3: Básica (Primera Capa) | B3: Responsable | C3: Identidad de la entidad que trata los datos. | D3: 1 | E3: Identifica de forma clara e inequívoca a la persona jurídica (UPM) y al departamento de investigación concreto que ejerce el control. | F3: "¿Quién usa tus datos? Si completas el cuestionario, aceptas que la Universidad Politécnica de Madrid use tus datos. El grupo responsable es el Grupo de Ingeniería Ontológica."
